Workbook
Name Slicer_Category: #N/A
Name Slicer_Region: #N/A
Name Slicer_Segment: #N/A
Name Slicer_Ship_Mode: #N/A
Name Slicer_Years: #N/A

Sheet Orders
A1: Row ID | B1: Order ID | C1: Order Date | D1: Ship Date | E1: Ship Mode | F1: Customer ID | G1: Customer Name | H1: Segment | I1: Country | J1: City | K1: State | L1: Postal Code | M1: Region | N1: Product ID | O1: Category | P1: Sub-Category | Q1: Product Name | R1: Sales | S1: Quantity | T1: Discount | U1: Profit | V1: Profit Margin
A2: 1 | B2: CA-2016-152156 | C2: 42682 | D2: 42685 | E2: Second Class | F2: CG-12520 | G2: Claire Gute | H2: Consumer | I2: United States | J2: Henderson | K2: Kentucky | L2: 42420 | M2: South | N2: FUR-BO-10001798 | O2: Furniture | P2: Bookcases | Q2: Bush Somerset Collection Bookcase | R2: 261.96 | S2: 2 | T2: 0 | U2: 41.9136 | V2: =U2/R2 -> 0.16
A3: 2 | B3: CA-2016-152156 | C3: 42682 | D3: 42685 | E3: Second Class | F3: CG-12520 | G3: Claire Gute | H3: Consumer | I3: United States | J3: Henderson | K3: Kentucky | L3: 42420 | M3: South | N3: FUR-CH-10000454 | O3: Furniture | P3: Chairs | Q3: Hon Deluxe Fabric Upholstered Stacking Chairs, Rounded Back | R3: 731.94 | S3: 3 | T3: 0 | U3: 219.582 | V3: =U3/R3 -> 0.3
A4: 3 | B4: CA-2016-138688 | C4: 42533 | D4: 42537 | E4: Second Class | F4: DV-13045 | G4: Darrin Van Huff | H4: Corporate | I4: United States | J4: Los Angeles | K4: California | L4: 90036 | M4: West | N4: OFF-LA-10000240 | O4: Office Supplies | P4: Labels | Q4: Self-Adhesive Address Labels for Typewriters by Universal | R4: 14.62 | S4: 2 | T4: 0 | U4: 6.8714 | V4: =U4/R4 -> 0.47
A5: 4 | B5: US-2015-108966 | C5: 42288 | D5: 42295 | E5: Standard Class | F5: SO-20335 | G5: Sean O'Donnell | H5: Consumer | I5: United States | J5: Fort Lauderdale | K5: Florida | L5: 33311 | M5: South | N5: FUR-TA-10000577 | O5: Furniture | P5: Tables | Q5: Bretford CR4500 Series Slim Rectangular Table | R5: 957.5775 | S5: 5 | T5: 0.45 | U5: -383.031 | V5: =U5/R5 -> -0.4
A6: 5 | B6: US-2015-108966 | C6: 42288 | D6: 42295 | E6: Standard Class | F6: SO-20335 | G6: Sean O'Donnell | H6: Consumer | I6: United States | J6: Fort Lauderdale | K6: Florida | L6: 33311 | M6: South | N6: OFF-ST-10000760 | O6: Office Supplies | P6: Storage | Q6: Eldon Fold 'N Roll Cart System | R6: 22.368 | S6: 2 | T6: 0.2 | U6: 2.5164 | V6: =U6/R6 -> 0.1125
A7: 6 | B7: CA-2014-115812 | C7: 41799 | D7: 41804 | E7: Standard Class | F7: BH-11710 | G7: Brosina Hoffman | H7: Consumer | I7: United States | J7: Los Angeles | K7: California | L7: 90032 | M7: West | N7: FUR-FU-10001487 | O7: Furniture | P7: Furnishings | Q7: Eldon Expressions Wood and Plastic Desk Accessories, Cherry Wood | R7: 48.86 | S7: 7 | T7: 0 | U7: 14.1694 | V7: =U7/R7 -> 0.29
A8: 7 | B8: CA-2014-115812 | C8: 41799 | D8: 41804 | E8: Standard Class | F8: BH-11710 | G8: Brosina Hoffman | H8: Consumer | I8: United States | J8: Los Angeles | K8: California | L8: 90032 | M8: West | N8: OFF-AR-10002833 | O8: Office Supplies | P8: Art | Q8: Newell 322 | R8: 7.28 | S8: 4 | T8: 0 | U8: 1.9656 | V8: =U8/R8 -> 0.27
A9: 8 | B9: CA-2014-115812 | C9: 41799 | D9: 41804 | E9: Standard Class | F9: BH-11710 | G9: Brosina Hoffman | H9: Consumer | I9: United States | J9: Los Angeles | K9: California | L9: 90032 | M9: West | N9: TEC-PH-10002275 | O9: Technology | P9: Phones | Q9: Mitel 5320 IP Phone VoIP phone | R9: 907.152 | S9: 6 | T9: 0.2 | U9: 90.7152 | V9: =U9/R9 -> 0.1
A10: 9 | B10: CA-2014-115812 | C10: 41799 | D10: 41804 | E10: Standard Class | F10: BH-11710 | G10: Brosina Hoffman | H10: Consumer | I10: United States | J10: Los Angeles | K10: California | L10: 90032 | M10: West | N10: OFF-BI-10003910 | O10: Office Supplies | P10: Binders | Q10: DXL Angle-View Binders with Locking Rings by Samsill | R10: 18.504 | S10: 3 | T10: 0.2 | U10: 5.7825 | V10: =U10/R10 -> 0.3125
A11: 10 | B11: CA-2014-115812 | C11: 41799 | D11: 41804 | E11: Standard Class | F11: BH-11710 | G11: Brosina Hoffman | H11: Consumer | I11: United States | J11: Los Angeles | K11: California | L11: 90032 | M11: West | N11: OFF-AP-10002892 | O11: Office Supplies | P11: Appliances | Q11: Belkin F5C206VTEL 6 Outlet Surge | R11: 114.9 | S11: 5 | T11: 0 | U11: 34.47 | V11: =U11/R11 -> 0.3
A12: 11 | B12: CA-2014-115812 | C12: 41799 | D12: 41804 | E12: Standard Class | F12: BH-11710 | G12: Brosina Hoffman | H12: Consumer | I12: United States | J12: Los Angeles | K12: California | L12: 90032 | M12: West | N12: FUR-TA-10001539 | O12: Furniture | P12: Tables | Q12: Chromcraft Rectangular Conference Tables | R12: 1706.184 | S12: 9 | T12: 0.2 | U12: 85.3092 | V12: =U12/R12 -> 0.05
A13: 12 | B13: CA-2014-115812 | C13: 41799 | D13: 41804 | E13: Standard Class | F13: BH-11710 | G13: Brosina Hoffman | H13: Consumer | I13: United States | J13: Los Angeles | K13: California | L13: 90032 | M13: West | N13: TEC-PH-10002033 | O13: Technology | P13: Phones | Q13: Konftel 250 Conference phone - Charcoal black | R13: 911.424 | S13: 4 | T13: 0.2 | U13: 68.3568 | V13: =U13/R13 -> 0.075
... A2235: 2234 | B2235: CA-2015-123232 | C2235: 42352 | D2235: 42354 | E2235: Second Class | F2235: DJ-13630 | G2235: Doug Jacobs | H2235: Consumer | I2235: United States | J2235: Portland | K2235: Oregon | L2235: 97206 | M2235: West | N2235: TEC-PH-10001051 | O2235: Technology | P2235: Phones | Q2235: HTC One | R2235: 319.968 | S2235: 4 | T2235: 0.2 | U2235: 35.9964 | V2235: =U2235/R2235 -> 0.1125
A2236: 2235 | B2236: CA-2017-104066 | C2236: 43074 | D2236: 43079 | E2236: Standard Class | F2236: QJ-19255 | G2236: Quincy Jones | H2236: Corporate | I2236: United States | J2236: Burlington | K2236: Vermont | L2236: 05408 | M2236: East | N2236: TEC-AC-10001013 | O2236: Technology | P2236: Accessories | Q2236: Logitech ClearChat Comfort/USB Headset H390 | R2236: 205.03 | S2236: 7 | T2236: 0 | U2236: 67.6599 | V2236: =U2236/R2236 -> 0.33
A2237: 2236 | B2237: CA-2015-145849 | C2237: 42262 | D2237: 42264 | E2237: Second Class | F2237: CT-11995 | G2237: Carol Triggs | H2237: Consumer | I2237: United States | J2237: Indianapolis | K2237: Indiana | L2237: 46203 | M2237: Central | N2237: OFF-ST-10000025 | O2237: Office Supplies | P2237: Storage | Q2237: Fellowes Stor/Drawer Steel Plus Storage Drawers | R2237: 190.86 | S2237: 2 | T2237: 0 | U2237: 11.4516 | V2237: =U2237/R2237 -> 0.06
A2238: 2237 | B2238: CA-2015-145849 | C2238: 42262 | D2238: 42264 | E2238: Second Class | F2238: CT-11995 | G2238: Carol Triggs | H2238: Consumer | I2238: United States | J2238: Indianapolis | K2238: Indiana | L2238: 46203 | M2238: Central | N2238: OFF-AR-10000817 | O2238: Office Supplies | P2238: Art | Q2238: Manco Dry-Lighter Erasable Highlighter | R2238: 24.32 | S2238: 8 | T2238: 0 | U2238: 8.2688 | V2238: =U2238/R2238 -> 0.34
A2239: 2238 | B2239: CA-2016-122322 | C2239: 42566 | D2239: 42572 | E2239: Standard Class | F2239: RH-19510 | G2239: Rick Huthwaite | H2239: Home Office | I2239: United States | J2239: Provo | K2239: Utah | L2239: 84604 | M2239: West | N2239: OFF-SU-10000952 | O2239: Office Supplies | P2239: Supplies | Q2239: Fiskars Home & Office Scissors | R2239: 44.4 | S2239: 5 | T2239: 0 | U2239: 12.432 | V2239: =U2239/R2239 -> 0.28
A2240: 2239 | B2240: CA-2017-166849 | C2240: 42845 | D2240: 42851 | E2240: Standard Class | F2240: SJ-20125 | G2240: Sanjit Jacobs | H2240: Home Office | I2240: United States | J2240: Chicago | K2240: Illinois | L2240: 60610 | M2240: Central | N2240: FUR-FU-10004597 | O2240: Furniture | P2240: Furnishings | Q2240: Eldon Cleatmat Chair Mats for Medium Pile Carpets | R2240: 44.4 | S2240: 2 | T2240: 0.6 | U2240: -52.17 | V2240: =U2240/R2240 -> -1.175
A2241: 2240 | B2241: CA-2016-146633 | C2241: 42689 | D2241: 42691 | E2241: Second Class | F2241: TG-21310 | G2241: Toby Gnade | H2241: Consumer | I2241: United States | J2241: Los Angeles | K2241: California | L2241: 90049 | M2241: West | N2241: OFF-BI-10003527 | O2241: Office Supplies | P2241: Binders | Q2241: Fellowes PB500 Electric Punch Plastic Comb Binding Machine with Manual Bind | R2241: 1016.792 | S2241: 1 | T2241: 0.2 | U2241: 381.297 | V2241: =U2241/R2241 -> 0.375
A2242: 2241 | B2242: CA-2016-146633 | C2242: 42689 | D2242: 42691 | E2242: Second Class | F2242: TG-21310 | G2242: Toby Gnade | H2242: Consumer | I2242: United States | J2242: Los Angeles | K2242: California | L2242: 90049 | M2242: West | N2242: OFF-BI-10002982 | O2242: Office Supplies | P2242: Binders | Q2242: Avery Self-Adhesive Photo Pockets for Polaroid Photos | R2242: 38.136 | S2242: 7 | T2242: 0.2 | U2242: 13.3476 | V2242: =U2242/R2242 -> 0.35
A2243: 2242 | B2243: US-2016-126893 | C2243: 42700 | D2243: 42705 | E2243: Standard Class | F2243: CT-11995 | G2243: Carol Triggs | H2243: Consumer | I2243: United States | J2243: Philadelphia | K2243: Pennsylvania | L2243: 19134 | M2243: East | N2243: TEC-PH-10004165 | O2243: Technology | P2243: Phones | Q2243: Mitel MiVoice 5330e IP Phone | R2243: 494.982 | S2243: 3 | T2243: 0.4 | U2243: -115.4958 | V2243: =U2243/R2243 -> -0.23333333
A2244: 2243 | B2244: CA-2017-103380 | C2244: 43060 | D2244: 43064 | E2244: Standard Class | F2244: BF-11005 | G2244: Barry Franz | H2244: Home Office | I2244: United States | J2244: Pasadena | K2244: California | L2244: 91104 | M2244: West | N2244: OFF-ST-10003442 | O2244: Office Supplies | P2244: Storage | Q2244: Eldon Portable Mobile Manager | R2244: 56.56 | S2244: 2 | T2244: 0 | U2244: 15.2712 | V2244: =U2244/R2244 -> 0.27
A2245: 2244 | B2245: CA-2017-103380 | C2245: 43060 | D2245: 43064 | E2245: Standard Class | F2245: BF-11005 | G2245: Barry Franz | H2245: Home Office | I2245: United States | J2245: Pasadena | K2245: California | L2245: 91104 | M2245: West | N2245: OFF-AR-10003856 | O2245: Office Supplies | P2245: Art | Q2245: Newell 344 | R2245: 5.56 | S2245: 2 | T2245: 0 | U2245: 1.4456 | V2245: =U2245/R2245 -> 0.26
A2246: 2245 | B2246: CA-2017-103380 | C2246: 43060 | D2246: 43064 | E2246: Standard Class | F2246: BF-11005 | G2246: Barry Franz | H2246: Home Office | I2246: United States | J2246: Pasadena | K2246: California | L2246: 91104 | M2246: West | N2246: OFF-FA-10004248 | O2246: Office Supplies | P2246: Fasteners | Q2246: Advantus T-Pin Paper Clips | R2246: 9.02 | S2246: 2 | T2246: 0 | U2246: 3.5178 | V2246: =U2246/R2246 -> 0.39
A2247: 2246 | B2247: CA-2017-103380 | C2247: 43060 | D2247: 43064 | E2247: Standard Class | F2247: BF-11005 | G2247: Barry Franz | H2247: Home Office | I2247: United States | J2247: Pasadena | K2247: California | L2247: 91104 | M2247: West | N2247: OFF-AP-10001492 | O2247: Office Supplies | P2247: Appliances | Q2247: Acco Six-Outlet Power Strip, 4' Cord Length | R2247: 8.62 | S2247: 1 | T2247: 0 | U2247: 2.2412 | V2247: =U2247/R2247 -> 0.26
A2248: 2247 | B2248: CA-2017-103380 | C2248: 43060 | D2248: 43064 | E2248: Standard Class | F2248: BF-11005 | G2248: Barry Franz | H2248: Home Office | I2248: United States | J2248: Pasadena | K2248: California | L2248: 91104 | M2248: West | N2248: TEC-PH-10004165 | O2248: Technology | P2248: Phones | Q2248: Mitel MiVoice 5330e IP Phone | R2248: 659.976 | S2248: 3 | T2248: 0.2 | U2248: 49.4982 | V2248: =U2248/R2248 -> 0.075
... A5275: 5274 | B5275: US-2016-158309 | C5275: 42700 | D5275: 42703 | E5275: First Class | F5275: PA-19060 | G5275: Pete Armstrong | H5275: Home Office | I5275: United States | J5275: Miami | K5275: Florida | L5275: 33142 | M5275: South | N5275: OFF-BI-10000145 | O5275: Office Supplies | P5275: Binders | Q5275: Zipper Ring Binder Pockets | R5275: 3.744 | S5275: 4 | T5275: 0.7 | U5275: -2.6208 | V5275: =U5275/R5275 -> -0.7
A5276: 5275 | B5276: CA-2015-162887 | C5276: 42315 | D5276: 42317 | E5276: Second Class | F5276: SV-20785 | G5276: Stewart Visinsky | H5276: Consumer | I5276: United States | J5276: Burlington | K5276: Vermont | L5276: 05408 | M5276: East | N5276: FUR-CH-10000595 | O5276: Furniture | P5276: Chairs | Q5276: Safco Contoured Stacking Chairs | R5276: 715.2 | S5276: 3 | T5276: 0 | U5276: 178.8 | V5276: =U5276/R5276 -> 0.25
A5277: 5276 | B5277: CA-2017-147333 | C5277: 43083 | D5277: 43089 | E5277: Standard Class | F5277: KL-16555 | G5277: Kelly Lampkin | H5277: Corporate | I5277: United States | J5277: Fayetteville | K5277: Arkansas | L5277: 72701 | M5277: South | N5277: TEC-AC-10004469 | O5277: Technology | P5277: Accessories | Q5277: Microsoft Sculpt Comfort Mouse | R5277: 159.8 | S5277: 4 | T5277: 0 | U5277: 70.312 | V5277: =U5277/R5277 -> 0.44
A5278: 5277 | B5278: CA-2017-147333 | C5278: 43083 | D5278: 43089 | E5278: Standard Class | F5278: KL-16555 | G5278: Kelly Lampkin | H5278: Corporate | I5278: United States | J5278: Fayetteville | K5278: Arkansas | L5278: 72701 | M5278: South | N5278: TEC-AC-10003038 | O5278: Technology | P5278: Accessories | Q5278: Kingston Digital DataTraveler 16GB USB 2.0 | R5278: 44.75 | S5278: 5 | T5278: 0 | U5278: 8.5025 | V5278: =U5278/R5278 -> 0.19
A5279: 5278 | B5279: CA-2014-113859 | C5279: 41895 | D5279: 41899 | E5279: Standard Class | F5279: BC-11125 | G5279: Becky Castell | H5279: Home Office | I5279: United States | J5279: Odessa | K5279: Texas | L5279: 79762 | M5279: Central | N5279: FUR-CH-10004698 | O5279: Furniture | P5279: Chairs | Q5279: Padded Folding Chairs, Black, 4/Carton | R5279: 340.116 | S5279: 6 | T5279: 0.3 | U5279: -9.7176 | V5279: =U5279/R5279 -> -0.028571429
A5280: 5279 | B5280: CA-2014-159681 | C5280: 41980 | D5280: 41986 | E5280: Standard Class | F5280: PO-18850 | G5280: Patrick O'Brill | H5280: Consumer | I5280: United States | J5280: Virginia Beach | K5280: Virginia | L5280: 23464 | M5280: South | N5280: OFF-PA-10003641 | O5280: Office Supplies | P5280: Paper | Q5280: Xerox 1909 | R5280: 105.52 | S5280: 4 | T5280: 0 | U5280: 48.5392 | V5280: =U5280/R5280 -> 0.46
A5281: 5280 | B5281: US-2017-104094 | C5281: 42985 | D5281: 42989 | E5281: Standard Class | F5281: AG-10675 | G5281: Anna Gayman | H5281: Consumer | I5281: United States | J5281: Milwaukee | K5281: Wisconsin | L5281: 53209 | M5281: Central | N5281: TEC-AC-10002134 | O5281: Technology | P5281: Accessories | Q5281: Rosewill 107 Normal Keys USB Wired Standard Keyboard | R5281: 13.48 | S5281: 1 | T5281: 0 | U5281: 1.8872 | V5281: =U5281/R5281 -> 0.14
A5282: 5281 | B5282: CA-2017-152709 | C5282: 43015 | D5282: 43020 | E5282: Standard Class | F5282: DB-13210 | G5282: Dean Braden | H5282: Consumer | I5282: United States | J5282: Detroit | K5282: Michigan | L5282: 48234 | M5282: Central | N5282: OFF-ST-10001837 | O5282: Office Supplies | P5282: Storage | Q5282: SAFCO Mobile Desk Side File, Wire Frame | R5282: 85.52 | S5282: 2 | T5282: 0 | U5282: 22.2352 | V5282: =U5282/R5282 -> 0.26
A5283: 5282 | B5283: CA-2015-105158 | C5283: 42252 | D5283: 42257 | E5283: Standard Class | F5283: SP-20860 | G5283: Sung Pak | H5283: Corporate | I5283: United States | J5283: Rochester | K5283: Minnesota | L5283: 55901 | M5283: Central | N5283: FUR-FU-10001706 | O5283: Furniture | P5283: Furnishings | Q5283: Longer-Life Soft White Bulbs | R5283: 6.16 | S5283: 2 | T5283: 0 | U5283: 2.9568 | V5283: =U5283/R5283 -> 0.48
A5284: 5283 | B5284: CA-2015-105158 | C5284: 42252 | D5284: 42257 | E5284: Standard Class | F5284: SP-20860 | G5284: Sung Pak | H5284: Corporate | I5284: United States | J5284: Rochester | K5284: Minnesota | L5284: 55901 | M5284: Central | N5284: OFF-PA-10001970 | O5284: Office Supplies | P5284: Paper | Q5284: Xerox 1881 | R5284: 36.84 | S5284: 3 | T5284: 0 | U5284: 17.3148 | V5284: =U5284/R5284 -> 0.47
A5285: 5284 | B5285: CA-2014-133424 | C5285: 41728 | D5285: 41733 | E5285: Standard Class | F5285: Dl-13600 | G5285: Dorris liebe | H5285: Corporate | I5285: United States | J5285: Seattle | K5285: Washington | L5285: 98105 | M5285: West | N5285: OFF-ST-10002957 | O5285: Office Supplies | P5285: Storage | Q5285: Sterilite Show Offs Storage Containers | R5285: 15.84 | S5285: 3 | T5285: 0 | U5285: 0 | V5285: =U5285/R5285 -> 0
A5286: 5285 | B5286: CA-2014-133424 | C5286: 41728 | D5286: 41733 | E5286: Standard Class | F5286: Dl-13600 | G5286: Dorris liebe | H5286: Corporate | I5286: United States | J5286: Seattle | K5286: Washington | L5286: 98105 | M5286: West | N5286: OFF-LA-10002312 | O5286: Office Supplies | P5286: Labels | Q5286: Avery 490 | R5286: 44.4 | S5286: 3 | T5286: 0 | U5286: 22.2 | V5286: =U5286/R5286 -> 0.5
A5287: 5286 | B5287: CA-2017-105991 | C5287: 42860 | D5287: 42861 | E5287: First Class | F5287: LH-17020 | G5287: Lisa Hazard | H5287: Consumer | I5287: United States | J5287: Louisville | K5287: Colorado | L5287: 80027 | M5287: West | N5287: OFF-EN-10002600 | O5287: Office Supplies | P5287: Envelopes | Q5287: Redi-Strip #10 Envelopes, 4 1/8 x 9 1/2 | R5287: 21.24 | S5287: 9 | T5287: 0.2 | U5287: 7.434 | V5287: =U5287/R5287 -> 0.35
...

Sheet Sheet1

Sheet Sheet2
A2: Claire Gute
A3: Darrin Van Huff
A4: Sean O'Donnell
A5: Brosina Hoffman
A6: Andrew Allen
A7: Irene Maddox
A8: Harold Pawlan
A9: Pete Kriz
A10: Alejandro Grove
A11: Zuschuss Donatelli
A12: Ken Black
A13: Sandra Flanagan
... A794: Susan MacKendrick

Sheet Dashboard
A1: Super Store Sales - Dashboard
A4: Total Sales: | B4: =SUM(Orders!R321:'Orders'!R9995) -> 2213541.1 | D4: Sum of Sales | K4: Sum of Sales
A5: Total Profit: | B5: =SUM(Orders!U2:'Orders'!U9995) -> 286397.02 | D5: Category | E5: Total | K5: Years | L5: Quarters | M5: Order Date | N5: Total
A6: Total Quantity: | B6: =SUM(Orders!S2:'Orders'!S9995) -> 37873 | D6: Technology | E6: 836154.03 | K6: 2014 | L6: Qtr1 | M6: Jan | N6: 14236.895
A7: Profit Per Order: | B7: =B5/COUNTA(Orders!B2:'Orders'!B9995) -> 28.656896 | D7: Furniture | E7: 741999.8 | M7: Feb | N7: 4519.892 | Z7: 132.4 | AA7: 13059.144
A8: Total Profit Margin: | B8: =SUM(Orders!V2:'Orders'!V9995) -> 1202.4174 | D8: Office Supplies | E8: 719047.03 | M8: Mar | N8: 55691.009 | Z8: 105 | AA8: 26590.166
A9: Total Customer: | B9: =793 -> 793 | D9: Grand Total | E9: 2297200.9 | L9: Qtr2 | M9: Apr | N9: 28295.345 | Z9: 83.35 | AA9: -17725.481
M10: May | N10: 23648.287 | Z10: 48.14 | AA10: -3472.556
M11: Jun | N11: 34595.128 | Z11: 368.89 | AA11: 18451.273
A12: Sum of Sales | L12: Qtr3 | M12: Jul | N12: 33946.393 | Z12: 567 | AA12: 30221.763
A13: Ship Mode | B13: Total | M13: Aug | N13: 27909.468 | Z13: 102.6 | AA13: 34053.569
A14: First Class | B14: 351428.42 | M14: Sep | N14: 81777.351 | Z14: 77.6 | AA14: 18138.005
A15: Same Day | B15: 128363.12 | L15: Qtr4 | M15: Oct | N15: 31453.393 | Z15: 63.2 | AA15: 21278.826
A16: Second Class | B16: 459193.57 | D16: Sum of Sales | M16: Nov | N16: 78628.717 | Z16: 59.6 | AA16: 6527.787
A17: Standard Class | B17: 1358215.7 | D17: Region | E17: Total | M17: Dec | N17: 69545.62 | Z17: 25 | AA17: 5546.254
A18: Grand Total | B18: 2297200.9 | D18: West | E18: 725457.82 | K18: 2015 | L18: Qtr1 | M18: Jan | N18: 18174.076 | Z18: 20.4 | AA18: 6964.1767
D19: East | E19: 678781.24 | M19: Feb | N19: 11951.411 | Q19: Data | Z19: 17.8 | AA19: 949.5182
D20: Central | E20: 501239.89 | M20: Mar | N20: 38726.252 | P20: Category | Q20: Sum of Sales | R20: Sum of Profit | Z20: 14.6 | AA20: -1189.0995
D21: South | E21: 391721.91 | L21: Qtr2 | M21: Apr | N21: 34195.208 | P21: Technology | Q21: 836154.03 | R21: 145454.95 | Z21: 947.8 | AA21: 122490.8
D22: Grand Total | E22: 2297200.9 | M22: May | N22: 30131.686 | P22: Furniture | Q22: 741999.8 | R22: 18451.273 | Z22: 137.4 | AA22: 44515.731
M23: Jun | N23: 24797.292 | P23: Office Supplies | Q23: 719047.03 | R23: 122490.8 | Z23: 60.8 | AA23: 41936.636
L24: Qtr3 | M24: Jul | N24: 28765.325 | P24: Grand Total | Q24: 2297200.9 | R24: 286397.02 | Z24: 35.2 | AA24: 3384.7569
M25: Aug | N25: 36898.332 | Z25: 11 | AA25: 55617.825
M26: Sep | N26: 64595.918 | Z26: 244.4 | AA26: 145454.95
D27: Sum of Sales | L27: Qtr4 | M27: Oct | N27: 31404.924
D28: Segment | E28: Total | M28: Nov | N28: 75972.564
D29: Consumer | E29: 1161401.3 | M29: Dec | N29: 74919.521
D30: Corporate | E30: 706146.37 | K30: 2016 | L30: Qtr1 | M30: Jan | N30: 18542.491 | AA30: Sum of Profit
D31: Home Office | E31: 429653.15 | M31: Feb | N31: 22978.815 | AA31: Years | AB31: Quarters | AC31: Order Date | AD31: Total
D32: Grand Total | E32: 2297200.9 | M32: Mar | N32: 51715.875 | Q32: Data | AA32: 2014 | AB32: Qtr1 | AC32: Jan | AD32: 2450.1907
L33: Qtr2 | M33: Apr | N33: 38750.039 | P33: Region | Q33: Sum of Sales | R33: Sum of Profit | AC33: Feb | AD33: 862.3084
M34: May | N34: 56987.728 | P34: West | Q34: 725457.82 | R34: 108418.45 | AC34: Mar | AD34: 498.7299
M35: Jun | N35: 40344.534 | P35: East | Q35: 678781.24 | R35: 91522.78 | AB35: Qtr2 | AC35: Apr | AD35: 3488.8352
L36: Qtr3 | M36: Jul | N36: 39261.963 | P36: Central | Q36: 501239.89 | R36: 39706.362 | AC36: May | AD36: 2738.7096
M37: Aug | N37: 31115.374 | P37: South | Q37: 391721.91 | R37: 46749.43 | AC37: Jun | AD37: 4976.5244
M38: Sep | N38: 73410.025 | P38: Grand Total | Q38: 2297200.9 | R38: 286397.02 | AB38: Qtr3 | AC38: Jul | AD38: -841.4826
A39: Sum of Sales | L39: Qtr4 | M39: Oct | N39: 59687.745 | AC39: Aug | AD39: 5318.105
A40: Sub-Category | B40: Total | M40: Nov | N40: 79411.966 | AC40: Sep | AD40: 8328.0994
A41: Phones | B41: 330007.05 | M41: Dec | N41: 96999.043 | AB41: Qtr4 | AC41: Oct | AD41: 3448.2573
A42: Chairs | B42: 328449.1 | K42: 2017 | L42: Qtr1 | M42: Jan | N42: 43971.374 | AC42: Nov | AD42: 9292.1269
...

Sheet Sales & Profit Dashboard
A4: No of Orders | C4: Total Sales | E4: Total Profit | G4: Profit Margin | I4: Units Sold | K4: Total Customers
A5: =COUNTA(Table1[Order ID]) -> 9994 | C5: =SUM(Table1[Sales]) -> 2297200.9 | E5: =SUM(Table1[Profit]) -> 286397.02 | G5: =E5/C5 -> 0.12467217 | I5: =SUM(Table1[Quantity]) -> 37873 | K5: =Dashboard!$B$9 -> 793

Sheet Regional base Analysis
A4: Total Regions | C4: No of Orders
A5: =COUNTA(_xlfn.UNIQUE(Table1[Region])) -> 4 | C5: =COUNTA(Table1[Order ID]) -> 9994

Sheet Ship Mode base Analysis

Sheet Returns
A1: Returned | B1: Order ID
A2: Yes | B2: CA-2017-153822
A3: Yes | B3: CA-2017-129707
A4: Yes | B4: CA-2014-152345
A5: Yes | B5: CA-2015-156440
A6: Yes | B6: US-2017-155999
A7: Yes | B7: CA-2014-157924
A8: Yes | B8: CA-2017-131807
A9: Yes | B9: CA-2016-124527
A10: Yes | B10: CA-2017-135692
A11: Yes | B11: CA-2014-123225
A12: Yes | B12: CA-2017-145772
... A297: Yes | B297: CA-2015-149636

Sheet Customer Segment analysis
A4: Total Customers
A5: =COUNTA(_xlfn.UNIQUE(Table1[Customer ID])) -> 793

Sheet People
A1: Person | B1: Region
A2: Anna Andreadi | B2: West
A3: Chuck Magee | B3: East
A4: Kelly Williams | B4: Central
A5: Cassandra Brandow | B5: South
